2017-06-15 17:24:00 ERROR (MainThread) [homeassistant.config] Invalid config for [automation]: expected a dictionary @ data['condition'][0]. Got None
extra keys not allowed @ data['action'][0]['message']. Got None. (See C:\Users\RGonzalez\AppData\Roaming\.homeassistant\configuration.yaml, line 118). Please check the docs at https://home-assistant.io/components/automation/
2017-06-15 17:24:01 ERROR (<concurrent.futures.thread.ThreadPoolExecutor object at 0x00000000037B1CF8>_0) [homeassistant.util.yaml] while scanning for the next token
found character '\t' that cannot start any token
  in "C:\Users\RGonzalez\AppData\Roaming\.homeassistant\known_devices.yaml", line 2, column 1
2017-06-15 17:24:01 ERROR (MainThread) [homeassistant.components.device_tracker] Unable to load C:\Users\RGonzalez\AppData\Roaming\.homeassistant\known_devices.yaml: while scanning for the next token
found character '\t' that cannot start any token
  in "C:\Users\RGonzalez\AppData\Roaming\.homeassistant\known_devices.yaml", line 2, column 1
2017-06-15 17:24:04 ERROR (<concurrent.futures.thread.ThreadPoolExecutor object at 0x00000000037B1CF8>_3) [homeassistant.util.package] Unable to install package zeroconf==0.19.0: Command "c:\users\rgonzalez\appdata\local\programs\python\python36\python.exe -u -c "import setuptools, tokenize;__file__='C:\\Users\\RGONZA~1\\AppData\\Local\\Temp\\pip-build-t0ne2gyl\\netifaces\\setup.py';f=getattr(tokenize, 'open', open)(__file__);code=f.read().replace('\r\n', '\n');f.close();exec(compile(code, __file__, 'exec'))" install --record C:\Users\RGONZA~1\AppData\Local\Temp\pip-rln6gvt0-record\install-record.txt --single-version-externally-managed --compile --home=C:\Users\RGONZA~1\AppData\Local\Temp\tmps9fv0b9a" failed with error code 1 in C:\Users\RGONZA~1\AppData\Local\Temp\pip-build-t0ne2gyl\netifaces\
2017-06-15 17:24:04 ERROR (MainThread) [homeassistant.setup] Not initializing zeroconf because could not install dependency zeroconf==0.19.0
2017-06-15 17:24:04 ERROR (MainThread) [homeassistant.setup] Setup failed for zeroconf: Could not install all requirements.
2017-06-15 17:24:06 ERROR (<concurrent.futures.thread.ThreadPoolExecutor object at 0x00000000037B1CF8>_4) [pyicloud.base.http] Forbidden
2017-06-15 17:24:06 ERROR (<concurrent.futures.thread.ThreadPoolExecutor object at 0x00000000037B1CF8>_4) [homeassistant.components.device_tracker.icloud] Error logging into iCloud Service: ('Invalid email/password combination.', PyiCloudAPIResponseError('Forbidden',))
2017-06-15 17:24:06 ERROR (<concurrent.futures.thread.ThreadPoolExecutor object at 0x00000000037B1CF8>_4) [homeassistant.components.device_tracker.icloud] No ICLOUDTRACKERS added
2017-06-15 17:24:06 ERROR (MainThread) [homeassistant.components.device_tracker] Error setting up platform icloud
2017-06-15 17:24:06 ERROR (MainThread) [homeassistant.setup] Unable to setup dependencies of ios. Setup failed for dependencies: zeroconf
2017-06-15 17:24:06 ERROR (MainThread) [homeassistant.setup] Setup failed for ios: Could not setup all dependencies.
2017-06-15 17:24:22 ERROR (<concurrent.futures.thread.ThreadPoolExecutor object at 0x00000000037B1CF8>_2) [pyicloud.base.http] Forbidden
2017-06-15 17:24:22 ERROR (<concurrent.futures.thread.ThreadPoolExecutor object at 0x00000000037B1CF8>_2) [homeassistant.components.device_tracker.icloud] Error logging into iCloud Service: ('Invalid email/password combination.', PyiCloudAPIResponseError('Forbidden',))
2017-06-15 17:25:18 ERROR (MainThread) [homeassistant.core] Error doing job: Exception in callback async_track_utc_time_change.<locals>.pattern_time_change_listener(<Event time_changed[R]>) at c:\users\rgonzalez\appdata\local\programs\python\python36\lib\site-packages\homeassistant\helpers\event.py:272
Traceback (most recent call last):
  File "c:\users\rgonzalez\appdata\local\programs\python\python36\lib\asyncio\events.py", line 127, in _run
    self._callback(*self._args)
  File "c:\users\rgonzalez\appdata\local\programs\python\python36\lib\site-packages\homeassistant\helpers\event.py", line 275, in pattern_time_change_listener
    now = event.data[ATTR_NOW]
KeyError: 'now'
2017-06-15 17:25:18 ERROR (MainThread) [homeassistant.core] Error doing job: Exception in callback async_track_point_in_utc_time.<locals>.point_in_time_listener(<Event time_changed[R]>) at c:\users\rgonzalez\appdata\local\programs\python\python36\lib\site-packages\homeassistant\helpers\event.py:139
Traceback (most recent call last):
  File "c:\users\rgonzalez\appdata\local\programs\python\python36\lib\asyncio\events.py", line 127, in _run
    self._callback(*self._args)
  File "c:\users\rgonzalez\appdata\local\programs\python\python36\lib\site-packages\homeassistant\helpers\event.py", line 142, in point_in_time_listener
    now = event.data[ATTR_NOW]
KeyError: 'now'
2017-06-15 17:25:18 ERROR (MainThread) [homeassistant.core] Error doing job: Exception in callback async_track_utc_time_change.<locals>.pattern_time_change_listener(<Event time_changed[R]>) at c:\users\rgonzalez\appdata\local\programs\python\python36\lib\site-packages\homeassistant\helpers\event.py:272
Traceback (most recent call last):
  File "c:\users\rgonzalez\appdata\local\programs\python\python36\lib\asyncio\events.py", line 127, in _run
    self._callback(*self._args)
  File "c:\users\rgonzalez\appdata\local\programs\python\python36\lib\site-packages\homeassistant\helpers\event.py", line 275, in pattern_time_change_listener
    now = event.data[ATTR_NOW]
KeyError: 'now'
2017-06-15 17:25:18 ERROR (MainThread) [homeassistant.core] Error doing job: Exception in callback async_track_utc_time_change.<locals>.pattern_time_change_listener(<Event time_changed[R]>) at c:\users\rgonzalez\appdata\local\programs\python\python36\lib\site-packages\homeassistant\helpers\event.py:272
Traceback (most recent call last):
  File "c:\users\rgonzalez\appdata\local\programs\python\python36\lib\asyncio\events.py", line 127, in _run
    self._callback(*self._args)
  File "c:\users\rgonzalez\appdata\local\programs\python\python36\lib\site-packages\homeassistant\helpers\event.py", line 275, in pattern_time_change_listener
    now = event.data[ATTR_NOW]
KeyError: 'now'
2017-06-15 17:25:18 ERROR (MainThread) [homeassistant.core] Error doing job: Exception in callback async_track_utc_time_change.<locals>.pattern_time_change_listener(<Event time_changed[R]>) at c:\users\rgonzalez\appdata\local\programs\python\python36\lib\site-packages\homeassistant\helpers\event.py:272
Traceback (most recent call last):
  File "c:\users\rgonzalez\appdata\local\programs\python\python36\lib\asyncio\events.py", line 127, in _run
    self._callback(*self._args)
  File "c:\users\rgonzalez\appdata\local\programs\python\python36\lib\site-packages\homeassistant\helpers\event.py", line 275, in pattern_time_change_listener
    now = event.data[ATTR_NOW]
KeyError: 'now'
2017-06-15 17:25:22 ERROR (<concurrent.futures.thread.ThreadPoolExecutor object at 0x00000000037B1CF8>_9) [pyicloud.base.http] Forbidden
2017-06-15 17:25:22 ERROR (<concurrent.futures.thread.ThreadPoolExecutor object at 0x00000000037B1CF8>_9) [homeassistant.components.device_tracker.icloud] Error logging into iCloud Service: ('Invalid email/password combination.', PyiCloudAPIResponseError('Forbidden',))
2017-06-15 17:26:22 ERROR (<concurrent.futures.thread.ThreadPoolExecutor object at 0x00000000037B1CF8>_0) [pyicloud.base.http] Forbidden
2017-06-15 17:26:22 ERROR (<concurrent.futures.thread.ThreadPoolExecutor object at 0x00000000037B1CF8>_0) [homeassistant.components.device_tracker.icloud] Error logging into iCloud Service: ('Invalid email/password combination.', PyiCloudAPIResponseError('Forbidden',))
2017-06-15 17:27:22 ERROR (<concurrent.futures.thread.ThreadPoolExecutor object at 0x00000000037B1CF8>_4) [pyicloud.base.http] Forbidden
2017-06-15 17:27:22 ERROR (<concurrent.futures.thread.ThreadPoolExecutor object at 0x00000000037B1CF8>_4) [homeassistant.components.device_tracker.icloud] Error logging into iCloud Service: ('Invalid email/password combination.', PyiCloudAPIResponseError('Forbidden',))
2017-06-15 17:28:22 ERROR (<concurrent.futures.thread.ThreadPoolExecutor object at 0x00000000037B1CF8>_5) [pyicloud.base.http] Forbidden
2017-06-15 17:28:22 ERROR (<concurrent.futures.thread.ThreadPoolExecutor object at 0x00000000037B1CF8>_5) [homeassistant.components.device_tracker.icloud] Error logging into iCloud Service: ('Invalid email/password combination.', PyiCloudAPIResponseError('Forbidden',))
2017-06-15 17:29:22 ERROR (<concurrent.futures.thread.ThreadPoolExecutor object at 0x00000000037B1CF8>_6) [pyicloud.base.http] Forbidden
2017-06-15 17:29:22 ERROR (<concurrent.futures.thread.ThreadPoolExecutor object at 0x00000000037B1CF8>_6) [homeassistant.components.device_tracker.icloud] Error logging into iCloud Service: ('Invalid email/password combination.', PyiCloudAPIResponseError('Forbidden',))
2017-06-15 17:29:45 WARNING (MainThread) [aiohttp.websocket] websocket connection is closing.
